<?xml version="1.0" ?>
<!-- =================================================================================== -->
<!-- |    This document was autogenerated by xacro from /home/arc/catkin_ws/src/phoenixbot/phoenixbot_description/urdf/phoenixbot.urdf.xacro | -->
<!-- |    EDITING THIS FILE BY HAND IS NOT RECOMMENDED                                 | -->
<!-- =================================================================================== -->
<robot name="phoenixbot" xmlns:xacro="http://www.ros.org/wiki/xacro">
  <gazebo>
    <plugin filename="libgazebo_ros_control.so" name="gazebo_ros_control">
      <robotSimType>gazebo_ros_control/DefaultRobotHWSim</robotSimType>
    </plugin>
  </gazebo>
  <link name="base_link"/>
  <joint name="base_link_joint" type="fixed">
    <parent link="base_link"/>
    <child link="chassis"/>
    <origin xyz="0 0 0.0254"/>
  </joint>
  <link name="chassis">
    <visual>
      <geometry>
        <box size="0.719074 0.6985 0.084582"/>
      </geometry>
    </visual>
    <collision>
      <geometry>
        <box size="0.719074 0.6985 0.084582"/>
      </geometry>
    </collision>
    <inertial>
      <mass value="6.80388"/>
      <inertia ixx="0.297228366542" ixy="0" ixz="0" iyy="0.569807751762" iyz="0" izz="0.280692008235"/>
    </inertial>
  </link>
  <link name="left_wheel">
    <visual>
      <origin rpy="1.57079632679 0 0"/>
      <geometry>
        <cylinder length="0.0254" radius="0.0508"/>
      </geometry>
    </visual>
    <collision>
      <origin rpy="1.57079632679 0 0"/>
      <geometry>
        <cylinder length="0.0254" radius="0.0508"/>
      </geometry>
    </collision>
    <inertial>
      <mass value="0.14061352"/>
      <inertia ixx="9.82780701101e-05" ixy="0" ixz="0" iyy="9.82780701101e-05" iyz="0" izz="9.82780701101e-05"/>
    </inertial>
  </link>
  <link name="left_fwheel">
    <visual>
      <origin rpy="1.57079632679 0 0"/>
      <geometry>
        <cylinder length="0.0254" radius="0.0508"/>
      </geometry>
    </visual>
    <collision>
      <origin rpy="1.57079632679 0 0"/>
      <geometry>
        <cylinder length="0.0254" radius="0.0508"/>
      </geometry>
    </collision>
    <inertial>
      <mass value="0.14061352"/>
      <inertia ixx="9.82780701101e-05" ixy="0" ixz="0" iyy="9.82780701101e-05" iyz="0" izz="9.82780701101e-05"/>
    </inertial>
  </link>
  <link name="left_rwheel">
    <visual>
      <origin rpy="1.57079632679 0 0"/>
      <geometry>
        <cylinder length="0.0254" radius="0.0508"/>
      </geometry>
    </visual>
    <collision>
      <origin rpy="1.57079632679 0 0"/>
      <geometry>
        <cylinder length="0.0254" radius="0.0508"/>
      </geometry>
    </collision>
    <inertial>
      <mass value="0.14061352"/>
      <inertia ixx="9.82780701101e-05" ixy="0" ixz="0" iyy="9.82780701101e-05" iyz="0" izz="9.82780701101e-05"/>
    </inertial>
  </link>
  <joint name="left_wheel_joint" type="continuous">
    <axis xyz="0 1 0"/>
    <origin xyz="0 0.325628 0"/>
    <parent link="base_link"/>
    <child link="left_wheel"/>
  </joint>
  <joint name="left_fwheel_joint" type="continuous">
    <axis xyz="0 1 0"/>
    <origin xyz="0.272542 0.325628 0.00635"/>
    <parent link="base_link"/>
    <child link="left_fwheel"/>
    <mimic joint="left_wheel_joint"/>
  </joint>
  <joint name="left_rwheel_joint" type="continuous">
    <axis xyz="0 1 0"/>
    <origin xyz="-0.272542 0.325628 0.00635"/>
    <parent link="base_link"/>
    <child link="left_rwheel"/>
    <mimic joint="left_wheel_joint"/>
  </joint>
  <link name="right_wheel">
    <visual>
      <origin rpy="1.57079632679 0 0"/>
      <geometry>
        <cylinder length="0.0254" radius="0.0508"/>
      </geometry>
    </visual>
    <collision>
      <origin rpy="1.57079632679 0 0"/>
      <geometry>
        <cylinder length="0.0254" radius="0.0508"/>
      </geometry>
    </collision>
    <inertial>
      <mass value="0.14061352"/>
      <inertia ixx="9.82780701101e-05" ixy="0" ixz="0" iyy="9.82780701101e-05" iyz="0" izz="9.82780701101e-05"/>
    </inertial>
  </link>
  <link name="right_fwheel">
    <visual>
      <origin rpy="1.57079632679 0 0"/>
      <geometry>
        <cylinder length="0.0254" radius="0.0508"/>
      </geometry>
    </visual>
    <collision>
      <origin rpy="1.57079632679 0 0"/>
      <geometry>
        <cylinder length="0.0254" radius="0.0508"/>
      </geometry>
    </collision>
    <inertial>
      <mass value="0.14061352"/>
      <inertia ixx="9.82780701101e-05" ixy="0" ixz="0" iyy="9.82780701101e-05" iyz="0" izz="9.82780701101e-05"/>
    </inertial>
  </link>
  <link name="right_rwheel">
    <visual>
      <origin rpy="1.57079632679 0 0"/>
      <geometry>
        <cylinder length="0.0254" radius="0.0508"/>
      </geometry>
    </visual>
    <collision>
      <origin rpy="1.57079632679 0 0"/>
      <geometry>
        <cylinder length="0.0254" radius="0.0508"/>
      </geometry>
    </collision>
    <inertial>
      <mass value="0.14061352"/>
      <inertia ixx="9.82780701101e-05" ixy="0" ixz="0" iyy="9.82780701101e-05" iyz="0" izz="9.82780701101e-05"/>
    </inertial>
  </link>
  <joint name="right_wheel_joint" type="continuous">
    <axis xyz="0 1 0"/>
    <origin xyz="0 -0.325628 0"/>
    <parent link="base_link"/>
    <child link="right_wheel"/>
  </joint>
  <joint name="right_fwheel_joint" type="continuous">
    <axis xyz="0 1 0"/>
    <origin xyz="0.272542 -0.325628 0.00635"/>
    <parent link="base_link"/>
    <child link="right_fwheel"/>
    <mimic joint="right_wheel_joint"/>
  </joint>
  <joint name="right_rwheel_joint" type="continuous">
    <axis xyz="0 1 0"/>
    <origin xyz="-0.272542 -0.325628 0.00635"/>
    <parent link="base_link"/>
    <child link="right_rwheel"/>
    <mimic joint="right_wheel_joint"/>
  </joint>
  <transmission name="left_wheel_transmission">
    <type>transmission_interface/SimpleTransmission</type>
    <joint name="left_wheel_joint">
      <hardwareInterface>hardware_interface/VelocityJointInterface</hardwareInterface>
    </joint>
    <actuator name="left_motor">
      <hardwareInterface>hardware_interface/VelocityJointInterface</hardwareInterface>
      <mechanicalReduction>1</mechanicalReduction>
    </actuator>
  </transmission>
  <transmission name="right_wheel_transmission">
    <type>transmission_interface/SimpleTransmission</type>
    <joint name="right_wheel_joint">
      <hardwareInterface>hardware_interface/VelocityJointInterface</hardwareInterface>
    </joint>
    <actuator name="right_motor">
      <hardwareInterface>hardware_interface/VelocityJointInterface</hardwareInterface>
      <mechanicalReduction>1</mechanicalReduction>
    </actuator>
  </transmission>
</robot>
